test_login_success_1 (test_cases.test_login_ddt.TestLogin) ... ERROR
test_login_success_2 (test_cases.test_login_ddt.TestLogin) ... ERROR
test_login_success_1 (test_cases.test_login_log.TestLogin) ... ERROR
test_login_success_2 (test_cases.test_login_log.TestLogin) ... ERROR
test_newfold_success (test_cases.test_newfold.LoginTest) ... ERROR
test_newfold_success (test_cases.test_newfold_token.LoginTest) ... ERROR
test_cases.test_register (unittest.loader._FailedTest) ... ERROR

======================================================================
ERROR: test_login_success_1 (test_cases.test_login_ddt.TestLogin)
----------------------------------------------------------------------
Traceback (most recent call last):
  File "C:\Users\Admin\AppData\Local\Programs\Python\Python38\lib\site-packages\urllib3\connectionpool.py", line 696, in urlopen
    self._prepare_proxy(conn)
  File "C:\Users\Admin\AppData\Local\Programs\Python\Python38\lib\site-packages\urllib3\connectionpool.py", line 964, in _prepare_proxy
    conn.connect()
  File "C:\Users\Admin\AppData\Local\Programs\Python\Python38\lib\site-packages\urllib3\connection.py", line 364, in connect
    conn = self._connect_tls_proxy(hostname, conn)
  File "C:\Users\Admin\AppData\Local\Programs\Python\Python38\lib\site-packages\urllib3\connection.py", line 501, in _connect_tls_proxy
    socket = ssl_wrap_socket(
  File "C:\Users\Admin\AppData\Local\Programs\Python\Python38\lib\site-packages\urllib3\util\ssl_.py", line 453, in ssl_wrap_socket
    ssl_sock = _ssl_wrap_socket_impl(sock, context, tls_in_tls)
  File "C:\Users\Admin\AppData\Local\Programs\Python\Python38\lib\site-packages\urllib3\util\ssl_.py", line 495, in _ssl_wrap_socket_impl
    return ssl_context.wrap_socket(sock)
  File "C:\Users\Admin\AppData\Local\Programs\Python\Python38\lib\ssl.py", line 500, in wrap_socket
    return self.sslsocket_class._create(
  File "C:\Users\Admin\AppData\Local\Programs\Python\Python38\lib\ssl.py", line 1040, in _create
    self.do_handshake()
  File "C:\Users\Admin\AppData\Local\Programs\Python\Python38\lib\ssl.py", line 1309, in do_handshake
    self._sslobj.do_handshake()
ssl.SSLError: [SSL: WRONG_VERSION_NUMBER] wrong version number (_ssl.c:1123)

During handling of the above exception, another exception occurred:

Traceback (most recent call last):
  File "C:\Users\Admin\AppData\Local\Programs\Python\Python38\lib\site-packages\requests\adapters.py", line 440, in send
    resp = conn.urlopen(
  File "C:\Users\Admin\AppData\Local\Programs\Python\Python38\lib\site-packages\urllib3\connectionpool.py", line 755, in urlopen
    retries = retries.increment(
  File "C:\Users\Admin\AppData\Local\Programs\Python\Python38\lib\site-packages\urllib3\util\retry.py", line 574, in increment
    raise MaxRetryError(_pool, url, error or ResponseError(cause))
urllib3.exceptions.MaxRetryError: HTTPSConnectionPool(host='userapi.edrawsoft.cn', port=443): Max retries exceeded with url: /api/user/login (Caused by SSLError(SSLError(1, '[SSL: WRONG_VERSION_NUMBER] wrong version number (_ssl.c:1123)')))

During handling of the above exception, another exception occurred:

Traceback (most recent call last):
  File "C:\Users\Admin\AppData\Local\Programs\Python\Python38\lib\site-packages\ddt.py", line 191, in wrapper
    return func(self, *args, **kwargs)
  File "D:\1test\PycharmProject\ApiTest_mindmaster\test_cases\test_login_ddt.py", line 23, in test_login_success
    res = self.req.visit(url=items['url'],
  File "D:\1test\PycharmProject\ApiTest_mindmaster\common\requests_handler.py", line 7, in visit
    result = self.session.request(method,url,params=params,data=data,json=json,headers=headers)
  File "C:\Users\Admin\AppData\Local\Programs\Python\Python38\lib\site-packages\requests\sessions.py", line 529, in request
    resp = self.send(prep, **send_kwargs)
  File "C:\Users\Admin\AppData\Local\Programs\Python\Python38\lib\site-packages\requests\sessions.py", line 645, in send
    r = adapter.send(request, **kwargs)
  File "C:\Users\Admin\AppData\Local\Programs\Python\Python38\lib\site-packages\requests\adapters.py", line 517, in send
    raise SSLError(e, request=request)
requests.exceptions.SSLError: HTTPSConnectionPool(host='userapi.edrawsoft.cn', port=443): Max retries exceeded with url: /api/user/login (Caused by SSLError(SSLError(1, '[SSL: WRONG_VERSION_NUMBER] wrong version number (_ssl.c:1123)')))

======================================================================
ERROR: test_login_success_2 (test_cases.test_login_ddt.TestLogin)
----------------------------------------------------------------------
Traceback (most recent call last):
  File "C:\Users\Admin\AppData\Local\Programs\Python\Python38\lib\site-packages\urllib3\connectionpool.py", line 696, in urlopen
    self._prepare_proxy(conn)
  File "C:\Users\Admin\AppData\Local\Programs\Python\Python38\lib\site-packages\urllib3\connectionpool.py", line 964, in _prepare_proxy
    conn.connect()
  File "C:\Users\Admin\AppData\Local\Programs\Python\Python38\lib\site-packages\urllib3\connection.py", line 364, in connect
    conn = self._connect_tls_proxy(hostname, conn)
  File "C:\Users\Admin\AppData\Local\Programs\Python\Python38\lib\site-packages\urllib3\connection.py", line 501, in _connect_tls_proxy
    socket = ssl_wrap_socket(
  File "C:\Users\Admin\AppData\Local\Programs\Python\Python38\lib\site-packages\urllib3\util\ssl_.py", line 453, in ssl_wrap_socket
    ssl_sock = _ssl_wrap_socket_impl(sock, context, tls_in_tls)
  File "C:\Users\Admin\AppData\Local\Programs\Python\Python38\lib\site-packages\urllib3\util\ssl_.py", line 495, in _ssl_wrap_socket_impl
    return ssl_context.wrap_socket(sock)
  File "C:\Users\Admin\AppData\Local\Programs\Python\Python38\lib\ssl.py", line 500, in wrap_socket
    return self.sslsocket_class._create(
  File "C:\Users\Admin\AppData\Local\Programs\Python\Python38\lib\ssl.py", line 1040, in _create
    self.do_handshake()
  File "C:\Users\Admin\AppData\Local\Programs\Python\Python38\lib\ssl.py", line 1309, in do_handshake
    self._sslobj.do_handshake()
ssl.SSLError: [SSL: WRONG_VERSION_NUMBER] wrong version number (_ssl.c:1123)

During handling of the above exception, another exception occurred:

Traceback (most recent call last):
  File "C:\Users\Admin\AppData\Local\Programs\Python\Python38\lib\site-packages\requests\adapters.py", line 440, in send
    resp = conn.urlopen(
  File "C:\Users\Admin\AppData\Local\Programs\Python\Python38\lib\site-packages\urllib3\connectionpool.py", line 755, in urlopen
    retries = retries.increment(
  File "C:\Users\Admin\AppData\Local\Programs\Python\Python38\lib\site-packages\urllib3\util\retry.py", line 574, in increment
    raise MaxRetryError(_pool, url, error or ResponseError(cause))
urllib3.exceptions.MaxRetryError: HTTPSConnectionPool(host='userapi.edrawsoft.cn', port=443): Max retries exceeded with url: /api/user/login (Caused by SSLError(SSLError(1, '[SSL: WRONG_VERSION_NUMBER] wrong version number (_ssl.c:1123)')))

During handling of the above exception, another exception occurred:

Traceback (most recent call last):
  File "C:\Users\Admin\AppData\Local\Programs\Python\Python38\lib\site-packages\ddt.py", line 191, in wrapper
    return func(self, *args, **kwargs)
  File "D:\1test\PycharmProject\ApiTest_mindmaster\test_cases\test_login_ddt.py", line 23, in test_login_success
    res = self.req.visit(url=items['url'],
  File "D:\1test\PycharmProject\ApiTest_mindmaster\common\requests_handler.py", line 7, in visit
    result = self.session.request(method,url,params=params,data=data,json=json,headers=headers)
  File "C:\Users\Admin\AppData\Local\Programs\Python\Python38\lib\site-packages\requests\sessions.py", line 529, in request
    resp = self.send(prep, **send_kwargs)
  File "C:\Users\Admin\AppData\Local\Programs\Python\Python38\lib\site-packages\requests\sessions.py", line 645, in send
    r = adapter.send(request, **kwargs)
  File "C:\Users\Admin\AppData\Local\Programs\Python\Python38\lib\site-packages\requests\adapters.py", line 517, in send
    raise SSLError(e, request=request)
requests.exceptions.SSLError: HTTPSConnectionPool(host='userapi.edrawsoft.cn', port=443): Max retries exceeded with url: /api/user/login (Caused by SSLError(SSLError(1, '[SSL: WRONG_VERSION_NUMBER] wrong version number (_ssl.c:1123)')))

======================================================================
ERROR: test_login_success_1 (test_cases.test_login_log.TestLogin)
----------------------------------------------------------------------
Traceback (most recent call last):
  File "C:\Users\Admin\AppData\Local\Programs\Python\Python38\lib\site-packages\ddt.py", line 191, in wrapper
    return func(self, *args, **kwargs)
  File "D:\1test\PycharmProject\ApiTest_mindmaster\test_cases\test_login_log.py", line 30, in test_login_success
    res = self.req.visit(method=items['method'],url=items['url'],json=json.loads(items['payload']),
KeyError: 'payload'

======================================================================
ERROR: test_login_success_2 (test_cases.test_login_log.TestLogin)
----------------------------------------------------------------------
Traceback (most recent call last):
  File "C:\Users\Admin\AppData\Local\Programs\Python\Python38\lib\site-packages\ddt.py", line 191, in wrapper
    return func(self, *args, **kwargs)
  File "D:\1test\PycharmProject\ApiTest_mindmaster\test_cases\test_login_log.py", line 30, in test_login_success
    res = self.req.visit(method=items['method'],url=items['url'],json=json.loads(items['payload']),
KeyError: 'payload'

======================================================================
ERROR: test_newfold_success (test_cases.test_newfold.LoginTest)
----------------------------------------------------------------------
Traceback (most recent call last):
  File "C:\Users\Admin\AppData\Local\Programs\Python\Python38\lib\site-packages\urllib3\connectionpool.py", line 696, in urlopen
    self._prepare_proxy(conn)
  File "C:\Users\Admin\AppData\Local\Programs\Python\Python38\lib\site-packages\urllib3\connectionpool.py", line 964, in _prepare_proxy
    conn.connect()
  File "C:\Users\Admin\AppData\Local\Programs\Python\Python38\lib\site-packages\urllib3\connection.py", line 364, in connect
    conn = self._connect_tls_proxy(hostname, conn)
  File "C:\Users\Admin\AppData\Local\Programs\Python\Python38\lib\site-packages\urllib3\connection.py", line 501, in _connect_tls_proxy
    socket = ssl_wrap_socket(
  File "C:\Users\Admin\AppData\Local\Programs\Python\Python38\lib\site-packages\urllib3\util\ssl_.py", line 453, in ssl_wrap_socket
    ssl_sock = _ssl_wrap_socket_impl(sock, context, tls_in_tls)
  File "C:\Users\Admin\AppData\Local\Programs\Python\Python38\lib\site-packages\urllib3\util\ssl_.py", line 495, in _ssl_wrap_socket_impl
    return ssl_context.wrap_socket(sock)
  File "C:\Users\Admin\AppData\Local\Programs\Python\Python38\lib\ssl.py", line 500, in wrap_socket
    return self.sslsocket_class._create(
  File "C:\Users\Admin\AppData\Local\Programs\Python\Python38\lib\ssl.py", line 1040, in _create
    self.do_handshake()
  File "C:\Users\Admin\AppData\Local\Programs\Python\Python38\lib\ssl.py", line 1309, in do_handshake
    self._sslobj.do_handshake()
ssl.SSLError: [SSL: WRONG_VERSION_NUMBER] wrong version number (_ssl.c:1123)

During handling of the above exception, another exception occurred:

Traceback (most recent call last):
  File "C:\Users\Admin\AppData\Local\Programs\Python\Python38\lib\site-packages\requests\adapters.py", line 440, in send
    resp = conn.urlopen(
  File "C:\Users\Admin\AppData\Local\Programs\Python\Python38\lib\site-packages\urllib3\connectionpool.py", line 755, in urlopen
    retries = retries.increment(
  File "C:\Users\Admin\AppData\Local\Programs\Python\Python38\lib\site-packages\urllib3\util\retry.py", line 574, in increment
    raise MaxRetryError(_pool, url, error or ResponseError(cause))
urllib3.exceptions.MaxRetryError: HTTPSConnectionPool(host='userapi.edrawsoft.cn', port=443): Max retries exceeded with url: /api/user/login (Caused by SSLError(SSLError(1, '[SSL: WRONG_VERSION_NUMBER] wrong version number (_ssl.c:1123)')))

During handling of the above exception, another exception occurred:

Traceback (most recent call last):
  File "D:\1test\PycharmProject\ApiTest_mindmaster\test_cases\test_newfold.py", line 28, in test_newfold_success
    res = self.req.visit('post', login_url, json=payload)
  File "D:\1test\PycharmProject\ApiTest_mindmaster\common\requests_handler.py", line 7, in visit
    result = self.session.request(method,url,params=params,data=data,json=json,headers=headers)
  File "C:\Users\Admin\AppData\Local\Programs\Python\Python38\lib\site-packages\requests\sessions.py", line 529, in request
    resp = self.send(prep, **send_kwargs)
  File "C:\Users\Admin\AppData\Local\Programs\Python\Python38\lib\site-packages\requests\sessions.py", line 645, in send
    r = adapter.send(request, **kwargs)
  File "C:\Users\Admin\AppData\Local\Programs\Python\Python38\lib\site-packages\requests\adapters.py", line 517, in send
    raise SSLError(e, request=request)
requests.exceptions.SSLError: HTTPSConnectionPool(host='userapi.edrawsoft.cn', port=443): Max retries exceeded with url: /api/user/login (Caused by SSLError(SSLError(1, '[SSL: WRONG_VERSION_NUMBER] wrong version number (_ssl.c:1123)')))

======================================================================
ERROR: test_newfold_success (test_cases.test_newfold_token.LoginTest)
----------------------------------------------------------------------
Traceback (most recent call last):
  File "C:\Users\Admin\AppData\Local\Programs\Python\Python38\lib\site-packages\urllib3\connectionpool.py", line 696, in urlopen
    self._prepare_proxy(conn)
  File "C:\Users\Admin\AppData\Local\Programs\Python\Python38\lib\site-packages\urllib3\connectionpool.py", line 964, in _prepare_proxy
    conn.connect()
  File "C:\Users\Admin\AppData\Local\Programs\Python\Python38\lib\site-packages\urllib3\connection.py", line 364, in connect
    conn = self._connect_tls_proxy(hostname, conn)
  File "C:\Users\Admin\AppData\Local\Programs\Python\Python38\lib\site-packages\urllib3\connection.py", line 501, in _connect_tls_proxy
    socket = ssl_wrap_socket(
  File "C:\Users\Admin\AppData\Local\Programs\Python\Python38\lib\site-packages\urllib3\util\ssl_.py", line 453, in ssl_wrap_socket
    ssl_sock = _ssl_wrap_socket_impl(sock, context, tls_in_tls)
  File "C:\Users\Admin\AppData\Local\Programs\Python\Python38\lib\site-packages\urllib3\util\ssl_.py", line 495, in _ssl_wrap_socket_impl
    return ssl_context.wrap_socket(sock)
  File "C:\Users\Admin\AppData\Local\Programs\Python\Python38\lib\ssl.py", line 500, in wrap_socket
    return self.sslsocket_class._create(
  File "C:\Users\Admin\AppData\Local\Programs\Python\Python38\lib\ssl.py", line 1040, in _create
    self.do_handshake()
  File "C:\Users\Admin\AppData\Local\Programs\Python\Python38\lib\ssl.py", line 1309, in do_handshake
    self._sslobj.do_handshake()
ssl.SSLError: [SSL: WRONG_VERSION_NUMBER] wrong version number (_ssl.c:1123)

During handling of the above exception, another exception occurred:

Traceback (most recent call last):
  File "C:\Users\Admin\AppData\Local\Programs\Python\Python38\lib\site-packages\requests\adapters.py", line 440, in send
    resp = conn.urlopen(
  File "C:\Users\Admin\AppData\Local\Programs\Python\Python38\lib\site-packages\urllib3\connectionpool.py", line 755, in urlopen
    retries = retries.increment(
  File "C:\Users\Admin\AppData\Local\Programs\Python\Python38\lib\site-packages\urllib3\util\retry.py", line 574, in increment
    raise MaxRetryError(_pool, url, error or ResponseError(cause))
urllib3.exceptions.MaxRetryError: HTTPSConnectionPool(host='userapi.edrawsoft.cn', port=443): Max retries exceeded with url: /api/user/login (Caused by SSLError(SSLError(1, '[SSL: WRONG_VERSION_NUMBER] wrong version number (_ssl.c:1123)')))

During handling of the above exception, another exception occurred:

Traceback (most recent call last):
  File "D:\1test\PycharmProject\ApiTest_mindmaster\test_cases\test_newfold_token.py", line 23, in test_newfold_success
    token=save_token()
  File "D:\1test\PycharmProject\ApiTest_mindmaster\middleware\helper.py", line 25, in save_token
    res = login()
  File "D:\1test\PycharmProject\ApiTest_mindmaster\middleware\helper.py", line 16, in login
    req = requests.post(url=config.host + '/api/user/login', json=yaml_data)
  File "C:\Users\Admin\AppData\Local\Programs\Python\Python38\lib\site-packages\requests\api.py", line 117, in post
    return request('post', url, data=data, json=json, **kwargs)
  File "C:\Users\Admin\AppData\Local\Programs\Python\Python38\lib\site-packages\requests\api.py", line 61, in request
    return session.request(method=method, url=url, **kwargs)
  File "C:\Users\Admin\AppData\Local\Programs\Python\Python38\lib\site-packages\requests\sessions.py", line 529, in request
    resp = self.send(prep, **send_kwargs)
  File "C:\Users\Admin\AppData\Local\Programs\Python\Python38\lib\site-packages\requests\sessions.py", line 645, in send
    r = adapter.send(request, **kwargs)
  File "C:\Users\Admin\AppData\Local\Programs\Python\Python38\lib\site-packages\requests\adapters.py", line 517, in send
    raise SSLError(e, request=request)
requests.exceptions.SSLError: HTTPSConnectionPool(host='userapi.edrawsoft.cn', port=443): Max retries exceeded with url: /api/user/login (Caused by SSLError(SSLError(1, '[SSL: WRONG_VERSION_NUMBER] wrong version number (_ssl.c:1123)')))

======================================================================
ERROR: test_cases.test_register (unittest.loader._FailedTest)
----------------------------------------------------------------------
ImportError: Failed to import test module: test_cases.test_register
Traceback (most recent call last):
  File "C:\Users\Admin\AppData\Local\Programs\Python\Python38\lib\unittest\loader.py", line 436, in _find_test_path
    module = self._get_module_from_name(name)
  File "C:\Users\Admin\AppData\Local\Programs\Python\Python38\lib\unittest\loader.py", line 377, in _get_module_from_name
    __import__(name)
  File "D:\1test\PycharmProject\ApiTest_mindmaster\test_cases\test_register.py", line 4, in <module>
    from common.helper import generate_mobile
ModuleNotFoundError: No module named 'common.helper'


----------------------------------------------------------------------
Ran 7 tests in 240.253s

FAILED (errors=7)
